Workbook

Sheet 종합
A1: 소담김밥 월별손익계산서_2025 하반기
E2: 7월 | F2: 8월 | G2: 9월 | H2: 10월 | I2: 11월 | J2: 12월 | K2: 합 계 | L2: 2025하반기월평균소득
A3: 수입 | B3: 매장 매출 | E3: 43791500 | F3: 33446500 | G3: 46233500 | H3: 40746000 | I3: 45819450 | J3: 49811000 | K3: =SUM(E3:J3) | L3: =K3/6
B4: 쿠팡 정산금 | E4: =쿠팡인출내역!C33 | F4: =쿠팡인출내역!F33 | G4: =쿠팡인출내역!I33 | H4: =쿠팡인출내역!L33 | I4: =쿠팡인출내역!O33 | J4: =쿠팡인출내역!R33 | K4: =SUM(E4:J4) | L4: =K4/6
B5: 배민 정산금 | E5: 3405467 | F5: 2078495 | G5: 2892424 | H5: 3339488 | I5: 2737557 | J5: 3276507 | K5: =SUM(E5:J5) | L5: =K5/6
B6: 요기요 정산금 | E6: 191533 | F6: 120265 | G6: 153751 | H6: 286580 | I6: 285020 | J6: 426838 | K6: =SUM(E6:J6) | L6: =K6/6
B7: 땡겨요 정산금 | E7: 11670 | F7: 30150 | G7: 206823 | H7: 623601 | I7: 367512 | J7: 302249 | K7: =SUM(E7:J7) | L7: =K7/6
A8: 합 계 | E8: =SUM(E3:E7) | F8: =SUM(F3:F7) | G8: =SUM(G3:G7) | H8: =SUM(H3:H7) | I8: =SUM(I3:I7) | J8: =SUM(J3:J7) | K8: =SUM(K3:K7) | L8: =SUM(L3:L7)
A9: 지출 | B9: 인건비 | E9: 13851000 | F9: 11920400 | G9: 15195900 | H9: 14507000 | I9: 15176800 | J9: 15632400 | K9: =SUM(E9:J9) | L9: =K9/6
B10: 임대관리비 | E10: ='7월비용'!AG46 | F10: ='8월비용'!AG47 | G10: ='9월비용'!AF44 | H10: ='10월비용'!AG44 | I10: ='11월비용'!AG44 | J10: ='12월비용'!AG47 | K10: =SUM(E10:J10) | L10: =K10/6
B11: 제세공과금(기타) | E11: ='7월비용'!AG43 | F11: ='8월비용'!AG44 | G11: ='9월비용'!AF41 | H11: ='10월비용'!AG41 | I11: ='11월비용'!AG41 | J11: ='12월비용'!AG44 | K11: =SUM(E11:J11) | L11: =K11/6
B12: 부가가치세 | E12: 4298650 | G12: 0 | H12: 4694000 | K12: =SUM(E12:J12) | L12: =K12/6
B13: 사업소득세 | E13: 286810 | F13: 307820 | G13: 97240 | H13: 347800 | J13: 267100 | K13: =SUM(E13:J13) | L13: =K13/6
B14: 근로소득세 | E14: 254220 | F14: 271330 | H14: 100450 | J14: 111220 | K14: =SUM(E14:J14) | L14: =K14/6
B15: 카드수수료(0.2%) | E15: =E3*0.02 | F15: =F3*0.02 | G15: =G3*0.02 | H15: =H3*0.02 | I15: =I3*0.02 | J15: =J3*0.02 | K15: =SUM(E15:J15) | L15: =K15/6
B16: 재료비 | E16: ='7월비용'!AG29 | F16: ='8월비용'!AG29 | G16: ='9월비용'!AF28 | H16: ='10월비용'!AG28 | I16: ='11월비용'!AG28 | J16: ='12월비용'!AG30 | K16: =SUM(E16:J16) | L16: =K16/6
B17: 퇴직금적립 | E17: =E9*0.1 | F17: =F9*0.1 | G17: =G9*0.1 | H17: =H9*0.1 | I17: =I9*0.1 | J17: =J9*0.1 | K17: =SUM(E17:J17) | L17: =K17/6
A18: 합 계 | E18: =SUM(E9:E17) | F18: =SUM(F9:F17) | G18: =SUM(G9:G17) | H18: =SUM(H9:H17) | I18: =SUM(I9:I17) | J18: =SUM(J9:J17) | K18: =SUM(K9:K17) | L18: =SUM(L9:L17)
A19: 영업이익 | E19: =E8-E18 | F19: =F8-F18 | G19: =G8-G18 | H19: =H8-H18 | I19: =I8-I18 | J19: =J8-J18 | K19: =K8-K18 | L19: =L8-L18
I21: 월평균소득 | J21: Hong Ji Yeon | K21: 0.7 | L21: =L19*0.7
J22: 임 춘 우 | K22: 0.3 | L22: =L19*0.3

Sheet 쿠팡인출내역
A1: 쿠팡이츠 정산금 입금내역_2025하반기
A2: 7월 | B2: 1 | D2: 8월 | E2: 1 | G2: 9월 | H2: 1 | I2: 141109 | J2: 10월 | K2: 1 | L2: 199452 | M2: 11월 | N2: 1 | P2: 12월 | Q2: 1 | R2: 237845
B3: 2 | E3: 2 | H3: 2 | I3: 291884 | K3: 2 | N3: 2 | Q3: 2 | R3: 252876
B4: 3 | E4: 3 | H4: 3 | K4: 3 | L4: 573921 | N4: 3 | Q4: 3
B5: 4 | E5: 4 | H5: 4 | K5: 4 | N5: 4 | Q5: 4 | R5: 933839
B6: 5 | E6: 5 | F6: 591901 | H6: 5 | I6: 728223 | K6: 5 | N6: 5 | O6: 967193 | Q6: 5 | R6: 310003
B7: 6 | E7: 6 | H7: 6 | K7: 6 | N7: 6 | O7: 811994 | Q7: 6
B8: 7 | C8: 1063307 | E8: 7 | H8: 7 | K8: 7 | N8: 7 | Q8: 7
B9: 8 | E9: 8 | H9: 8 | I9: 187626 | K9: 8 | N9: 8 | Q9: 8 | R9: 251121
B10: 9 | E10: 9 | F10: 638867 | H10: 9 | K10: 9 | N10: 9 | Q10: 9 | R10: 241283
B11: 10 | E11: 10 | H11: 10 | I11: 621834 | K11: 10 | L11: 267431 | N11: 10 | O11: 685162 | Q11: 10
B12: 11 | E12: 11 | F12: 150934 | H12: 11 | I12: 555735 | K12: 11 | N12: 11 | O12: 274603 | Q12: 11
B13: 12 | E13: 12 | H13: 12 | K13: 12 | N13: 12 | O13: 219602 | Q13: 12 | R13: 1028344
B14: 13 | E14: 13 | H14: 13 | K14: 13 | N14: 13 | O14: 554491 | Q14: 13
B15: 14 | E15: 14 | F15: 513643 | H15: 14 | K15: 14 | L15: 522921 | N15: 14 | O15: 294386 | Q15: 14
B16: 15 | C16: 1016360 | E16: 15 | H16: 15 | I16: 412704 | K16: 15 | N16: 15 | Q16: 15 | R16: 241279
B17: 16 | E17: 16 | H17: 16 | K17: 16 | L17: 1261276 | N17: 16 | Q17: 16
B18: 17 | E18: 17 | H18: 17 | K18: 17 | L18: 174737 | N18: 17 | O18: 256902 | Q18: 17 | R18: 485863
B19: 18 | C19: 619782 | E19: 18 | H19: 18 | I19: 513547 | K19: 18 | N19: 18 | Q19: 18 | R19: 423036
B20: 19 | E20: 19 | H20: 19 | K20: 19 | N20: 19 | O20: 451768 | Q20: 19 | R20: 271449
B21: 20 | E21: 20 | H21: 20 | K21: 20 | L21: 254504 | N21: 20 | O21: 509472 | Q21: 20
B22: 21 | E22: 21 | H22: 21 | K22: 21 | L22: 170953 | N22: 21 | O22: 260168 | Q22: 21
B23: 22 | C23: 181630 | E23: 22 | F23: 171258 | H23: 22 | K23: 22 | L23: 193757 | N23: 22 | Q23: 22 | R23: 204172
B24: 23 | E24: 23 | H24: 23 | I24: 585600 | K24: 23 | L24: 452871 | N24: 23 | Q24: 23 | R24: 201456
B25: 24 | C25: 514582 | E25: 24 | H25: 24 | K25: 24 | L25: 202180 | N25: 24 | O25: 240889 | Q25: 24 | R25: 131452
B26: 25 | C26: 106353 | E26: 25 | H26: 25 | I26: 488381 | K26: 25 | N26: 25 | O26: 204112 | Q26: 25
B27: 26 | E27: 26 | H27: 26 | I27: 277502 | K27: 26 | N27: 26 | O27: 177186 | Q27: 26 | R27: 354670
B28: 27 | E28: 27 | F28: 498564 | H28: 27 | K28: 27 | L28: 224675 | N28: 27 | O28: 572215 | Q28: 27
B29: 28 | E29: 28 | F29: 335880 | H29: 28 | K29: 28 | L29: 217028 | N29: 28 | O29: 283281 | Q29: 28
B30: 29 | C30: 336916 | E30: 29 | H30: 29 | I30: 149513 | K30: 29 | N30: 29 | Q30: 29 | R30: 310420
B31: 30 | E31: 30 | F31: 226676 | H31: 30 | I31: 176718 | K31: 30 | L31: 670943 | N31: 30 | Q31: 30 | R31: 169543
B32: 31 | C32: 496269 | E32: 31 | H32: 31 | K32: 31 | L32: 259504 | N32: 31 | Q32: 31 | R32: 247332
A33: 합 계 | C33: =SUM(C2:C32) | D33: 합 계 | F33: =SUM(F2:F32) | G33: 합 계 | I33: =SUM(I2:I32) | J33: 합 계 | L33: =SUM(L2:L32) | M33: 합 계 | O33: =SUM(O2:O32) | P33: 합 계 | R33: =SUM(R2:R32)

Sheet 7월비용
A1: 일별 거래내역서 (2025.9월)
B2: 1 | C2: 2 | D2: 3 | E2: 4 | F2: 5 | G2: 6 | H2: 7 | I2: 8 | J2: 9 | K2: 10 | L2: 11 | M2: 12 | N2: 13 | O2: 14 | P2: 15 | Q2: 16 | R2: 17 | S2: 18 | T2: 19 | U2: 20 | V2: 21 | W2: 22 | X2: 23 | Y2: 24 | Z2: 25 | AA2: 26 | AB2: 27 | AC2: 28 | AD2: 29 | AE2: 30 | AF2: 31
A3: 고구마켓 | C3: 381210 | J3: 163500 | K3: 169500 | N3: 56500 | O3: 226000 | V3: 339000 | AA3: 226000 | AE3: 395500 | AG3: =SUM(B3:AF3)
A4: 찬들농산 | D4: 140500 | H4: 43500 | I4: 70000 | K4: 66000 | O4: 98000 | R4: 36500 | S4: 34000 | V4: 84000 | W4: 34000 | Y4: 75000 | Z4: 67000 | AG4: =SUM(B4:AF4)
A5: 홍성상회 | D5: 64000 | H5: 64000 | O5: 128000 | R5: 32000 | W5: 64000 | AG5: =SUM(B5:AF5)
A6: 조양마트 | AG6: =SUM(B6:AF6)
A7: ㈜용담유통 | C7: 14600 | D7: 21900 | H7: 7300 | I7: 29200 | O7: 29200 | R7: 29200 | S7: 14600 | V7: 14000 | W7: 15200 | Y7: 14600 | Z7: 14600 | AG7: =SUM(B7:AF7)
A8: ㈜에코두레 | AG8: =SUM(B8:AF8)
A9: 코스트코 | S9: 247500 | AG9: =SUM(B9:AF9)
A10: 트레이더스 | AG10: =SUM(B10:AF10)
A11: 이마트 | AG11: =SUM(B11:AF11)
A12: 상대유통㈜ | AG12: =SUM(B12:AF12)
A13: 다농마트 | AG13: =SUM(B13:AF13)
A14: (주)유창 | AG14: =SUM(B14:AF14)
A15: 대한유통 | O15: 296000 | AF15: 1584800 | AG15: =SUM(B15:AF15)
A16: 재우상회 | AG16: =SUM(B16:AF16)
A17: ㈜에스에프앤비 | AG17: =SUM(B17:AF17)
A18: 용산식품 | AG18: =SUM(B18:AF18)
A19: 쿠팡 | E19: 115040 | H19: 7890 | M19: 16720 | P19: 16720 | Q19: 41130 | V19: 18110 | X19: 41550 | AB19: 22960 | AF19: 85130 | AG19: =SUM(B19:AF19)
A20: 배민상회 | AG20: =SUM(B20:AF20)
A21: 다인푸드닷컴 | AG21: =SUM(B21:AF21)
A22: ㈜한주주방아웃렛 | AG22: =SUM(B22:AF22)
A23: ㈜신진상사 | AG23: =SUM(B23:AF23)
A24: 창미포장기계(유용운) | V24: 65120 | AG24: =SUM(B24:AF24)
A25: 새로피엔엘 | AG25: =SUM(B25:AF25)
A26: 365하수구 | B26: 330000 | AG26: =SUM(B26:AF26)
A27: 세진햇김 | J27: 196000
A28: 태영유통 | AG28: =SUM(B28:AF28)
B29: =SUM(B3:B28) | C29: =SUM(C3:C28) | D29: =SUM(D3:D28) | E29: =SUM(E3:E28) | F29: =SUM(F3:F28) | G29: =SUM(G3:G28) | H29: =SUM(H3:H28) | I29: =SUM(I3:I28) | ... AD29: =SUM(AD3:AD28) | AF29: =SUM(AF3:AF28) | AG29: =SUM(B29:AF29)
A30: 포유인포텍 | H30: 5500 | AG30: =SUM(B30:AF30)
A31: 서울특징 | C31: 54070 | AG31: =SUM(B31:AF31)
A32: 국민건강보험 | K32: 1155760 | AG32: =SUM(B32:AF32)
A33: 국민연금 | K33: 329400 | AG33: =SUM(B33:AF33)
A34: 고용보험 | K34: 102780 | AG34: =SUM(B34:AF34)
A35: 산재보험 | K35: 90830 | AG35: =SUM(B35:AF35)
A36: SK인텔릭스 | AG36: =SUM(B36:AF36)
A37: SK매직 | K37: 25900
A38: KT통신요금 | V38: 22870 | AG38: =SUM(B38:AF38)
A39: 매리츠화재 | H39: 46190
A40: 한화손해보험 | H40: 30000
...

Sheet 8월비용
A1: 일별 거래내역서 (2025.9월)
B2: 1 | C2: 2 | D2: 3 | E2: 4 | F2: 5 | G2: 6 | H2: 7 | I2: 8 | J2: 9 | K2: 10 | L2: 11 | M2: 12 | N2: 13 | O2: 14 | P2: 15 | Q2: 16 | R2: 17 | S2: 18 | T2: 19 | U2: 20 | V2: 21 | W2: 22 | X2: 23 | Y2: 24 | Z2: 25 | AA2: 26 | AB2: 27 | AC2: 28 | AD2: 29 | AE2: 30 | AF2: 31
A3: 고구마켓(은제민) | C3: 169500 | G3: 226000 | L3: 172500 | T3: 292000 | Y3: 178500 | AG3: =SUM(B3:AF3)
A4: 찬들농산(김영민) | E4: 181500 | T4: 79000 | W4: 66000 | Z4: 70000 | AA4: 48000 | AC4: 22000 | AG4: =SUM(B4:AF4)
A5: 홍성상회(최희상) | F5: 128000 | Q5: 64000 | T5: 64000 | Z5: 64000 | AC5: 32000 | AG5: =SUM(B5:AF5)
A6: 조양마트 | AG6: =SUM(B6:AF6)
A7: ㈜용담유통 | E7: 43800 | F7: 14600 | T7: 14600 | AG7: =SUM(B7:AF7)
A8: ㈜에코두레 | AB8: 74250 | AG8: =SUM(B8:AF8)
A9: 코스트코 | AG9: =SUM(B9:AF9)
A10: 트레이더스 | AG10: =SUM(B10:AF10)
A11: 이마트 | AG11: =SUM(B11:AF11)
A12: 상대유통㈜ | AG12: =SUM(B12:AF12)
A13: 다농마트 | AG13: =SUM(B13:AF13)
A14: (주)유창 | AG14: =SUM(B14:AF14)
A15: 대한유통 | AG15: =SUM(B15:AF15)
A16: 재우상회 | AG16: =SUM(B16:AF16)
A17: ㈜에스에프앤비 | AG17: =SUM(B17:AF17)
A18: 용산식품 | AG18: =SUM(B18:AF18)
A19: 쿠팡 | D19: 42240 | H19: 7890 | I19: 21900 | L19: 43410 | R19: 53800 | U19: 59420 | AA19: 42000 | AB19: 41070 | AC19: 58650 | AD19: 221970 | AE19: 15500 | AG19: =SUM(B19:AF19)
A20: 배민상회 | AG20: =SUM(B20:AF20)
A21: 다인푸드닷컴 | AB21: 297500 | AG21: =SUM(B21:AF21)
A22: ㈜한주주방아웃렛 | AG22: =SUM(B22:AF22)
A23: ㈜신진상사 | AG23: =SUM(B23:AF23)
A24: 창미포장기계(유용운) | F24: 92620 | AG24: =SUM(B24:AF24)
A25: 새로피엔엘 | AG25: =SUM(B25:AF25)
A26: 365하수구 | AG26: =SUM(B26:AF26)
A27: 세진햇김
A28: 태영유통 | AG28: =SUM(B28:AF28)
B29: =SUM(B3:B28) | C29: =SUM(C3:C28) | D29: =SUM(D3:D28) | E29: =SUM(E3:E28) | F29: =SUM(F3:F28) | G29: =SUM(G3:G28) | H29: =SUM(H3:H28) | I29: =SUM(I3:I28) | ... AD29: =SUM(AD3:AD28) | AF29: =SUM(AF3:AF28) | AG29: =SUM(B29:AF29)
A30: 포유인포텍 | F30: 5500 | AG30: =SUM(B30:AF30)
A31: 서울특징 | AG31: =SUM(B31:AF31)
A32: 국민건강보험 | L32: 1119740 | AG32: =SUM(B32:AF32)
A33: 국민연금 | L33: 430200 | AG33: =SUM(B33:AF33)
A34: 고용보험 | L34: 125740 | AG34: =SUM(B34:AF34)
A35: 산재보험 | L35: 90830 | AG35: =SUM(B35:AF35)
A36: 서울주민세 | F36: 62500
A37: SK인텔릭스 | L37: 25900 | AG37: =SUM(B37:AF37)
A38: SK매직
A39: KT통신요금 | V39: 22870 | AG39: =SUM(B39:AF39)
A40: 매리츠화재 | F40: 46190
...

Sheet 9월비용
A1: 일별 거래내역서 (2025.9월)
B2: 1 | C2: 2 | D2: 3 | E2: 4 | F2: 5 | G2: 6 | H2: 7 | I2: 8 | J2: 9 | K2: 10 | L2: 11 | M2: 12 | N2: 13 | O2: 14 | P2: 15 | Q2: 16 | R2: 17 | S2: 18 | T2: 19 | U2: 20 | V2: 21 | W2: 22 | X2: 23 | Y2: 24 | Z2: 25 | AA2: 26 | AB2: 27 | AC2: 28 | AD2: 29 | AE2: 30
A3: 고구마켓(은제민) | B3: 240000 | D3: 183000 | J3: 186000 | K3: 248000 | Q3: 186000 | U3: 375000 | Y3: 317500 | AB3: 193500 | AF3: =SUM(B3:AE3)
A4: 찬들농산(김영민) | C4: 81000 | D4: 23000 | E4: 27000 | F4: 87000 | I4: 51000 | J4: 54000 | L4: 56000 | M4: 50000 | P4: 74000 | R4: 54000 | S4: 76000 | T4: 82000 | W4: 77900 | X4: 29000 | Z4: 70000 | AA4: 90000 | AD4: 28500 | AE4: 106000 | AF4: =SUM(B4:AE4)
A5: 홍성상회(최희상) | E5: 64000 | I5: 64000 | L5: 64000 | Q5: 64000 | S5: 32000 | X5: 64000 | Z5: 64000 | AD5: 64000 | AF5: =SUM(B5:AE5)
A6: 조양마트 | AF6: =SUM(B6:AE6)
A7: ㈜용담유통 | J7: 21900 | L7: 14600 | M7: 14600 | Q7: 21900 | S7: 14600 | T7: 14600 | X7: 14600 | Z7: 14600 | AA7: 21900 | AD7: 14600 | AE7: 7300 | AF7: =SUM(B7:AE7)
A8: ㈜에코두레 | B8: 123750 | I8: 286000 | K8: 74250 | T8: 99000 | AF8: =SUM(B8:AE8)
A9: 코스트코 | AF9: =SUM(B9:AE9)
A10: 트레이더스 | AF10: =SUM(B10:AE10)
A11: 이마트 | AF11: =SUM(B11:AE11)
A12: 상대유통㈜ | AF12: =SUM(B12:AE12)
A13: 다농마트 | AF13: =SUM(B13:AE13)
A14: (주)유창 | AF14: =SUM(B14:AE14)
A15: 대한유통 | C15: 26000 | AF15: =SUM(B15:AE15)
A16: 재우상회 | AF16: =SUM(B16:AE16)
A17: ㈜에스에프앤비 | AF17: =SUM(B17:AE17)
A18: 용산식품 | AF18: =SUM(B18:AE18)
A19: 쿠팡 | C19: 14850 | D19: 41790 | H19: 7890 | J19: 4720 | L19: 42240 | W19: 42991 | X19: 39900 | AA19: 41370 | AF19: =SUM(B19:AE19)
A20: 배민상회 | AF20: =SUM(B20:AE20)
A21: 다인푸드닷컴 | AF21: =SUM(B21:AE21)
A22: ㈜한주주방아웃렛 | AF22: =SUM(B22:AE22)
A23: ㈜신진상사 | AF23: =SUM(B23:AE23)
A24: 창미포장기계(유용운) | AF24: =SUM(B24:AE24)
A25: 에너지삼천 | T25: 440000
A26: 새로피엔엘 | AF26: =SUM(B26:AE26)
A27: 태영유통 | AF27: =SUM(B27:AE27)
B28: =SUM(B3:B27) | C28: =SUM(C3:C27) | D28: =SUM(D3:D27) | E28: =SUM(E3:E27) | F28: =SUM(F3:F27) | G28: =SUM(G3:G27) | H28: =SUM(H3:H27) | I28: =SUM(I3:I27) | ... AE28: =SUM(AE3:AE27) | AF28: =SUM(B28:AE28)
A29: 포유인포텍 | F29: 5500 | AF29: =SUM(B29:AE29)
A30: 서울특징 | J30: 9690 | AF30: =SUM(B30:AE30)
A31: 국민건강보험 | K31: 1119740 | AF31: =SUM(B31:AE31)
A32: 국민연금 | K32: 430200 | AF32: =SUM(B32:AE32)
A33: 고용보험 | K33: 125740 | AF33: =SUM(B33:AE33)
A34: 산재보험 | K34: 90830 | AF34: =SUM(B34:AE34)
A35: SK인텔릭스 | K35: 25900 | AF35: =SUM(B35:AE35)
A36: S1(N5851892) | F36: 44000
A37: 한화손해보험 | F37: 30000
A38: 메리츠화재 | F38: 46190
A39: KT통신요금 | W39: 22870 | AF39: =SUM(B39:AE39)
A40: CM보험 | AA40: 290500 | AF40: =SUM(B40:AE40)
...

Sheet 10월비용
A1: 일별 거래내역서 (2025.9월)
B2: 1 | C2: 2 | D2: 3 | E2: 4 | F2: 5 | G2: 6 | H2: 7 | I2: 8 | J2: 9 | K2: 10 | L2: 11 | M2: 12 | N2: 13 | O2: 14 | P2: 15 | Q2: 16 | R2: 17 | S2: 18 | T2: 19 | U2: 20 | V2: 21 | W2: 22 | X2: 23 | Y2: 24 | Z2: 25 | AA2: 26 | AB2: 27 | AC2: 28 | AD2: 29 | AE2: 30 | AF2: 31
A3: 고구마켓(은제민) | K3: 581000 | O3: 195000 | P3: 300000 | U3: 180000 | W3: 300000 | AB3: 180000 | AD3: 360000 | AG3: =SUM(B3:AF3)
A4: 찬들농산(김영민) | C4: 78000 | D4: 16300 | J4: 30000 | K4: 82000 | N4: 22000 | O4: 94000 | Q4: 49000 | R4: 89000 | U4: 22000 | V4: 101500 | Y4: 170000 | AB4: 26200 | AC4: 67000 | AF4: 72000 | AG4: =SUM(B4:AF4)
A5: 홍성상회(최희상) | J5: 64000 | N5: 64000 | R5: 64000 | U5: 64000 | X5: 32000 | AB5: 64000 | AE5: 32000 | AG5: =SUM(B5:AF5)
A6: 조양마트 | AG6: =SUM(B6:AF6)
A7: ㈜용담유통 | D7: 7300 | J7: 17600 | N7: 14400 | O7: 14400 | Q7: 13800 | U7: 14000 | V7: 13400 | X7: 14400 | Y7: 19100 | AB7: 13400 | AE7: 6600 | AF7: 19800 | AG7: =SUM(B7:AF7)
A8: ㈜에코두레 | C8: 49500 | Y8: 123750 | AG8: =SUM(B8:AF8)
A9: 코스트코 | AG9: =SUM(B9:AF9)
A10: 트레이더스 | AG10: =SUM(B10:AF10)
A11: 이마트 | AG11: =SUM(B11:AF11)
A12: 상대유통㈜ | AG12: =SUM(B12:AF12)
A13: 다농마트 | AG13: =SUM(B13:AF13)
A14: (주)유창 | AG14: =SUM(B14:AF14)
A15: 대한유통 | AG15: =SUM(B15:AF15)
A16: 재우상회 | AG16: =SUM(B16:AF16)
A17: ㈜에스에프앤비 | AG17: =SUM(B17:AF17)
A18: 용산식품 | AG18: =SUM(B18:AF18)
A19: 쿠팡 | B19: 21900 | H19: 7890 | J19: 104750 | L19: 40905 | N19: 18900 | P19: 164000 | U19: 161830 | W19: 39900 | X19: 16425 | Y19: 41340 | Z19: 39900 | AB19: 22200 | AC19: 17950 | AE19: 63030 | AG19: =SUM(B19:AF19)
A20: 배민상회 | AG20: =SUM(B20:AF20)
A21: 다인푸드닷컴 | AG21: =SUM(B21:AF21)
A22: ㈜한주주방아웃렛 | AG22: =SUM(B22:AF22)
A23: ㈜신진상사 | AG23: =SUM(B23:AF23)
A24: 창미포장기계(유용운) | N24: 67100 | AB24: 66200 | AG24: =SUM(B24:AF24)
A25: 에너지삼천 | AG25: =SUM(B25:AF25)
A26: 새로피엔엘 | AG26: =SUM(B26:AF26)
A27: 태영유통 | AG27: =SUM(B27:AF27)
B28: =SUM(B3:B27) | C28: =SUM(C3:C27) | D28: =SUM(D3:D27) | E28: =SUM(E3:E27) | F28: =SUM(F3:F27) | G28: =SUM(G3:G27) | H28: =SUM(H3:H27) | I28: =SUM(I3:I27) | ... AG28: =SUM(AG3:AG27)
A29: 포유인포텍 | P29: 5500 | AG29: =SUM(B29:AF29)
A30: 서울특징 | AG30: =SUM(B30:AF30)
A31: 국민건강보험 | K31: 74380 | AB31: 619650 | AG31: =SUM(B31:AF31)
A32: 국민연금 | K32: 43200 | AG32: =SUM(B32:AF32)
A33: 고용보험 | AG33: =SUM(B33:AF33)
A34: 산재보험 | K34: 4350 | AG34: =SUM(B34:AF34)
A35: SK인텔릭스 | O35: 25900 | AG35: =SUM(B35:AF35)
A36: S1(N5851892) | K36: 44000 | AG36: =SUM(B36:AF36)
A37: 한화손해보험 | K37: 30000 | AG37: =SUM(B37:AF37)
A38: 메리츠화재 | K38: 46190 | AG38: =SUM(B38:AF38)
A39: KT통신요금 | V39: 22870 | AG39: =SUM(B39:AF39)
A40: CM보험 | AB40: 290500 | AG40: =SUM(B40:AF40)
...

Sheet 11월비용
A1: 일별 거래내역서 (2025.9월)
B2: 1 | C2: 2 | D2: 3 | E2: 4 | F2: 5 | G2: 6 | H2: 7 | I2: 8 | J2: 9 | K2: 10 | L2: 11 | M2: 12 | N2: 13 | O2: 14 | P2: 15 | Q2: 16 | R2: 17 | S2: 18 | T2: 19 | U2: 20 | V2: 21 | W2: 22 | X2: 23 | Y2: 24 | Z2: 25 | AA2: 26 | AB2: 27 | AC2: 28 | AD2: 29 | AE2: 30 | AF2: 31
A3: 고구마켓(은제민) | E3: 240000 | G3: 60000 | L3: 247000 | M3: 360000 | S3: 180000 | T3: 360000 | Y3: 240000 | AA3: 360000 | AG3: =SUM(B3:AF3)
A4: 찬들농산(김영민) | F4: 161500 | G4: 64000 | K4: 137000 | L4: 78000 | M4: 22000 | N4: 28000 | O4: 110000 | R4: 42000 | S4: 75000 | U4: 50700 | V4: 112000 | Y4: 53000 | Z4: 33000 | AA4: 61400 | AB4: 40000 | AC4: 129000 | AG4: =SUM(B4:AF4)
A5: 홍성상회(최희상) | G5: 64000 | K5: 64000 | N5: 64000 | R5: 64000 | U5: 32000 | Y5: 64000 | AA5: 64000 | AG5: =SUM(B5:AF5)
A6: 조양마트 | AG6: =SUM(B6:AF6)
A7: ㈜용담유통 | AG7: =SUM(B7:AF7)
A8: ㈜에코두레 | H8: 123750 | AG8: =SUM(B8:AF8)
A9: 코스트코 | AG9: =SUM(B9:AF9)
A10: 트레이더스 | AG10: =SUM(B10:AF10)
A11: 이마트 | AG11: =SUM(B11:AF11)
A12: 상대유통㈜ | AG12: =SUM(B12:AF12)
A13: 다농마트 | AG13: =SUM(B13:AF13)
A14: (주)유창 | AG14: =SUM(B14:AF14)
A15: 대한유통 | D15: 296600 | AG15: =SUM(B15:AF15)
A16: 재우상회 | AG16: =SUM(B16:AF16)
A17: ㈜에스에프앤비 | AG17: =SUM(B17:AF17)
A18: 용산식품 | AG18: =SUM(B18:AF18)
A19: 쿠팡 | B19: 116150 | D19: 73000 | F19: 200240 | G19: 36511 | H19: 7890 | I19: 6500 | L19: 43650 | N19: 18900 | T19: 22500 | V19: 59900 | W19: 104900 | AA19: 118700 | AB19: 28701 | AD19: 100000 | AG19: =SUM(B19:AF19)
A20: 배민상회 | AG20: =SUM(B20:AF20)
A21: 다인푸드닷컴 | AG21: =SUM(B21:AF21)
A22: ㈜한주주방아웃렛 | AG22: =SUM(B22:AF22)
A23: ㈜신진상사 | AG23: =SUM(B23:AF23)
A24: 창미포장기계(유용운) | AG24: =SUM(B24:AF24)
A25: 에너지삼천 | AG25: =SUM(B25:AF25)
A26: 새로피엔엘 | AG26: =SUM(B26:AF26)
A27: 태영유통 | AG27: =SUM(B27:AF27)
B28: =SUM(B3:B27) | C28: =SUM(C3:C27) | D28: =SUM(D3:D27) | E28: =SUM(E3:E27) | F28: =SUM(F3:F27) | G28: =SUM(G3:G27) | H28: =SUM(H3:H27) | I28: =SUM(I3:I27) | ... AG28: =SUM(AG3:AG27)
A29: 포유인포텍 | F29: 5500 | AG29: =SUM(B29:AF29)
A30: 서울특징 | AG30: =SUM(B30:AF30)
A31: 국민건강보험 | K31: 1119740 | AG31: =SUM(B31:AF31)
A32: 국민연금 | K32: 41730 | Z32: 392350 | AG32: =SUM(B32:AF32)
A33: 고용보험 | K33: 10150 | AG33: =SUM(B33:AF33)
A34: 산재보험 | Z34: 54820 | AG34: =SUM(B34:AF34)
A35: SK인텔릭스 | K35: 25900 | AG35: =SUM(B35:AF35)
A36: S1(N5851892) | F36: 44000 | AG36: =SUM(B36:AF36)
A37: 한화손해보험 | F37: 30000 | AG37: =SUM(B37:AF37)
A38: 메리츠화재 | F38: 46190 | AG38: =SUM(B38:AF38)
A39: KT통신요금 | V39: 22870 | AG39: =SUM(B39:AF39)
A40: CM보험 | AA40: 290500 | AG40: =SUM(B40:AF40)
...

Sheet 12월비용
A1: 일별 거래내역서 (2025.9월)
B2: 1 | C2: 2 | D2: 3 | E2: 4 | F2: 5 | G2: 6 | H2: 7 | I2: 8 | J2: 9 | K2: 10 | L2: 11 | M2: 12 | N2: 13 | O2: 14 | P2: 15 | Q2: 16 | R2: 17 | S2: 18 | T2: 19 | U2: 20 | V2: 21 | W2: 22 | X2: 23 | Y2: 24 | Z2: 25 | AA2: 26 | AB2: 27 | AC2: 28 | AD2: 29 | AE2: 30 | AF2: 31
A3: 고구마켓(은제민) | B3: 180000 | I3: 615000 | O3: 360000 | P3: 180000 | T3: 360000 | X3: 180000 | AD3: 420000 | AG3: =SUM(B3:AF3)
A4: 찬들농산(김영민) | C4: 113800 | D4: 47000 | E4: 6000 | F4: 130000 | I4: 80000 | L4: 85000 | M4: 90800 | P4: 56000 | Q4: 71400 | S4: 49000 | T4: 114000 | W4: 52000 | AA4: 65000 | AD4: 97000 | AF4: 91500 | AG4: =SUM(B4:AF4)
A5: 홍성상회(최희상) | B5: 64000 | E5: 64000 | I5: 64000 | L5: 32000 | Q5: 64000 | S5: 32000 | W5: 64000 | AA5: 32000 | AD5: 64000 | AF5: 32000 | AG5: =SUM(B5:AF5)
A6: 조양마트 | AG6: =SUM(B6:AF6)
A7: ㈜용담유통 | AG7: =SUM(B7:AF7)
A8: ㈜에코두레 | K8: 409750 | X8: 247500 | AG8: =SUM(B8:AF8)
A9: 코스트코 | AG9: =SUM(B9:AF9)
A10: 트레이더스 | AG10: =SUM(B10:AF10)
A11: 이마트 | AG11: =SUM(B11:AF11)
A12: 상대유통㈜ | AG12: =SUM(B12:AF12)
A13: 다농마트 | AG13: =SUM(B13:AF13)
A14: (주)유창 | AG14: =SUM(B14:AF14)
A15: 대한유통 | AG15: =SUM(B15:AF15)
A16: 재우상회 | AG16: =SUM(B16:AF16)
A17: ㈜에스에프앤비 | AG17: =SUM(B17:AF17)
A18: 용산식품 | AG18: =SUM(B18:AF18)
A19: 쿠팡 | E19: 100000 | L19: 7890 | Q19: 100000 | T19: 400000 | AG19: =SUM(B19:AF19)
A20: 당근페이 | R20: 42000 | Z20: 10000
A21: 배민상회 | AG21: =SUM(B21:AF21)
A22: 다인푸드닷컴 | AG22: =SUM(B22:AF22)
A23: ㈜한주주방아웃렛 | AG23: =SUM(B23:AF23)
A24: ㈜신진상사 | AG24: =SUM(B24:AF24)
A25: 창미포장기계(유용운) | P25: 111120 | AG25: =SUM(B25:AF25)
A26: 에너지삼천 | AG26: =SUM(B26:AF26)
A27: 신영산업(김도희) | AF27: 94000
A28: 새로피엔엘 | P28: 280000 | AG28: =SUM(B28:AF28)
A29: 태영유통 | AG29: =SUM(B29:AF29)
B30: =SUM(B3:B29) | C30: =SUM(C3:C29) | D30: =SUM(D3:D29) | E30: =SUM(E3:E29) | F30: =SUM(F3:F29) | G30: =SUM(G3:G29) | H30: =SUM(H3:H29) | I30: =SUM(I3:I29) | ... AG30: =SUM(AG3:AG29)
A31: 포유인포텍 | F31: 5500 | AG31: =SUM(B31:AF31)
A32: 서울특징HON | D32: 37780 | AG32: =SUM(B32:AF32)
A33: 국민건강보험 | K33: 1119740 | AG33: =SUM(B33:AF33)
A34: 국민연금 | K34: 531000 | AG34: =SUM(B34:AF34)
A35: 고용보험 | K35: 11700 | AG35: =SUM(B35:AF35)
A36: 산재보험 | K36: 54030
A37: 예스코 | J37: 253639 | AG37: =SUM(B37:AF37)
A38: SK인텔릭스 | K38: 25900 | AG38: =SUM(B38:AF38)
A39: S1(N5851892) | F39: 44000 | AG39: =SUM(B39:AF39)
A40: 한화손해보험 | F40: 30000 | AG40: =SUM(B40:AF40)
...
